Workbook

Sheet Aggregate_Efficiency_BAU
A1: Scenarios - BAU 2025-2050
A2: Year | C2: 2017 | D2: 2018 | E2: 2019 | F2: 2020 | G2: 2021 | H2: 2022 | I2: 2023 | J2: 2024 | K2: 2025 | L2: 2026 | M2: 2027 | N2: 2028 | O2: 2029 | P2: 2030 | Q2: 2031 | R2: 2032 | S2: 2033 | T2: 2034 | U2: 2035 | V2: 2036 | W2: 2037 | X2: 2038 | Y2: 2039 | Z2: 2040 | AA2: 2041 | AB2: 2042 | AC2: 2043 | AD2: 2044 | AE2: 2045 | AF2: 2046 | AG2: 2047 | AH2: 2048 | AI2: 2049 | AJ2: 2050
A3: Total Final exergy [TJ] | C3: 1 | D3: 1 | E3: 1 | F3: 1 | G3: 1 | H3: 1 | I3: 1 | J3: 1 | K3: 1 | L3: 1 | M3: 1 | N3: 1 | O3: 1 | P3: 1 | Q3: 1 | R3: 1 | S3: 1 | T3: 1 | U3: 1 | V3: 1 | W3: 1 | X3: 1 | Y3: 1 | Z3: 1 | AA3: 1 | AB3: 1 | AC3: 1 | AD3: 1 | AE3: 1 | AF3: 1 | AG3: 1 | AH3: 1 | AI3: 1 | AJ3: 1
A5: Share final exergy industry [-] | B5: Input | C5: 0.27142931 | D5: 0.27119604 | E5: 0.2732505 | F5: 0.28555072 | G5: 0.28462773 | H5: 0.27572585 | I5: 0.25944504 | J5: 0.25617084 | K5: 0.25289663 | L5: 0.24962243 | M5: 0.24634823 | N5: 0.24307402 | O5: 0.23979982 | P5: 0.23652561 | Q5: 0.23325141 | R5: 0.2299772 | S5: 0.226703 | T5: 0.2234288 | U5: 0.22015459 | V5: 0.21688039 | W5: 0.21360618 | X5: 0.21033198 | Y5: 0.20705778 | Z5: 0.20378357 | AA5: 0.20050937 | AB5: 0.19723516 | AC5: 0.19396096 | AD5: 0.19068675 | AE5: 0.18741255 | AF5: 0.18413835 | AG5: 0.18086414 | AH5: 0.17758994 | AI5: 0.17431573 | AJ5: 0.17104153
A6: Share final exergy transport [-] | B6: Input | C6: 0.3546432 | D6: 0.35679786 | E6: 0.36315882 | F6: 0.32899597 | G6: 0.34997126 | H6: 0.36009084 | I6: 0.372118 | J6: 0.37430883 | K6: 0.37649966 | L6: 0.37869049 | M6: 0.38088132 | N6: 0.38307215 | O6: 0.38526298 | P6: 0.38745381 | Q6: 0.38964464 | R6: 0.39183547 | S6: 0.3940263 | T6: 0.39621713 | U6: 0.39840796 | V6: 0.40059879 | W6: 0.40278962 | X6: 0.40498045 | Y6: 0.40717127 | Z6: 0.4093621 | AA6: 0.41155293 | AB6: 0.41374376 | AC6: 0.41593459 | AD6: 0.41812542 | AE6: 0.42031625 | AF6: 0.42250708 | AG6: 0.42469791 | AH6: 0.42688874 | AI6: 0.42907957 | AJ6: 0.4312704
A7: Share final exergy services [-] | B7: Input | C7: 0.11098227 | D7: 0.11418082 | E7: 0.11117733 | F7: 0.10630522 | G7: 0.10424487 | H7: 0.10934643 | I7: 0.15300365 | J7: 0.15238571 | K7: 0.15176778 | L7: 0.15114984 | M7: 0.1505319 | N7: 0.14991396 | O7: 0.14929603 | P7: 0.14867809 | Q7: 0.14806015 | R7: 0.14744222 | S7: 0.14682428 | T7: 0.14620634 | U7: 0.1455884 | V7: 0.14497047 | W7: 0.14435253 | X7: 0.14373459 | Y7: 0.14311666 | Z7: 0.14249872 | AA7: 0.14188078 | AB7: 0.14126284 | AC7: 0.14064491 | AD7: 0.14002697 | AE7: 0.13940903 | AF7: 0.1387911 | AG7: 0.13817316 | AH7: 0.13755522 | AI7: 0.13693728 | AJ7: 0.13631935
A8: Share final exergy residencial [-] | B8: Input | C8: 0.15680348 | D8: 0.15992742 | E8: 0.15925696 | F8: 0.17964943 | G8: 0.17499831 | H8: 0.16410964 | I8: 0.12335774 | J8: 0.12518344 | K8: 0.12700913 | L8: 0.12883482 | M8: 0.13066052 | N8: 0.13248621 | O8: 0.1343119 | P8: 0.1361376 | Q8: 0.13796329 | R8: 0.13978899 | S8: 0.14161468 | T8: 0.14344037 | U8: 0.14526607 | V8: 0.14709176 | W8: 0.14891746 | X8: 0.15074315 | Y8: 0.15256884 | Z8: 0.15439454 | AA8: 0.15622023 | AB8: 0.15804592 | AC8: 0.15987162 | AD8: 0.16169731 | AE8: 0.16352301 | AF8: 0.1653487 | AG8: 0.16717439 | AH8: 0.16900009 | AI8: 0.17082578 | AJ8: 0.17265148
A9: Share Final Exergy Agriculture/forestry/Fishing [-] | B9: Input | C9: 0.027798035 | D9: 0.028064646 | E9: 0.028618365 | F9: 0.032768238 | G9: 0.03372055 | H9: 0.029928558 | I9: 0.023282591 | J9: 0.022797523 | K9: 0.022312456 | L9: 0.021827389 | M9: 0.021342321 | N9: 0.020857254 | O9: 0.020372187 | P9: 0.019887119 | Q9: 0.019402052 | R9: 0.018916984 | S9: 0.018431917 | T9: 0.01794685 | U9: 0.017461782 | V9: 0.016976715 | W9: 0.016491648 | X9: 0.01600658 | Y9: 0.015521513 | Z9: 0.015036446 | AA9: 0.014551378 | AB9: 0.014066311 | AC9: 0.013581244 | AD9: 0.013096176 | AE9: 0.012611109 | AF9: 0.012126042 | AG9: 0.011640974 | AH9: 0.011155907 | AI9: 0.01067084 | AJ9: 0.010185772
A10: Share Final Exergy Energy industry own use [-] | B10: Input | C10: 0.078343711 | D10: 0.069833206 | E10: 0.06453802 | F10: 0.066730424 | G10: 0.05243729 | H10: 0.060798684 | I10: 0.068792975 | J10: 0.06915366 | K10: 0.069514345 | L10: 0.06987503 | M10: 0.070235716 | N10: 0.070596401 | O10: 0.070957086 | P10: 0.071317771 | Q10: 0.071678456 | R10: 0.072039141 | S10: 0.072399826 | T10: 0.072760512 | U10: 0.073121197 | V10: 0.073481882 | W10: 0.073842567 | X10: 0.074203252 | Y10: 0.074563937 | Z10: 0.074924622 | AA10: 0.075285308 | AB10: 0.075645993 | AC10: 0.076006678 | AD10: 0.076367363 | AE10: 0.076728048 | AF10: 0.077088733 | AG10: 0.077449418 | AH10: 0.077810104 | AI10: 0.078170789 | AJ10: 0.078531474
A12: Final exergy Industry [TJ] | B12: Computed | C12: =+C5*C$3 -> 0.27142931 | D12: =+D5*D$3 -> 0.27119604 | E12: =+E5*E$3 -> 0.2732505 | F12: =+F5*F$3 -> 0.28555072 | G12: =+G5*G$3 -> 0.28462773 | H12: =+H5*H$3 -> 0.27572585 | I12: =+I5*I$3 -> 0.25944504 | J12: =+J5*J$3 -> 0.25617084 | ... AJ12: =+AJ5*AJ$3 -> 0.17104153
A13: Final exergy Transport [TJ] | B13: Computed | C13: =+C6*C$3 -> 0.3546432 | D13: =+D6*D$3 -> 0.35679786 | E13: =+E6*E$3 -> 0.36315882 | F13: =+F6*F$3 -> 0.32899597 | G13: =+G6*G$3 -> 0.34997126 | H13: =+H6*H$3 -> 0.36009084 | I13: =+I6*I$3 -> 0.372118 | J13: =+J6*J$3 -> 0.37430883 | ... AJ13: =+AJ6*AJ$3 -> 0.4312704
A14: Final exergy Services [TJ] | B14: Computed | C14: =+C7*C$3 -> 0.11098227 | D14: =+D7*D$3 -> 0.11418082 | E14: =+E7*E$3 -> 0.11117733 | F14: =+F7*F$3 -> 0.10630522 | G14: =+G7*G$3 -> 0.10424487 | H14: =+H7*H$3 -> 0.10934643 | I14: =+I7*I$3 -> 0.15300365 | J14: =+J7*J$3 -> 0.15238571 | ... AJ14: =+AJ7*AJ$3 -> 0.13631935
A15: Final exergy Residencial [TJ] | B15: Computed | C15: =+C8*C$3 -> 0.15680348 | D15: =+D8*D$3 -> 0.15992742 | E15: =+E8*E$3 -> 0.15925696 | F15: =+F8*F$3 -> 0.17964943 | G15: =+G8*G$3 -> 0.17499831 | H15: =+H8*H$3 -> 0.16410964 | I15: =+I8*I$3 -> 0.12335774 | J15: =+J8*J$3 -> 0.12518344 | ... AJ15: =+AJ8*AJ$3 -> 0.17265148
A16: Final Exergy Agriculture/Forestry/fishing [TJ] | B16: Computed | C16: =+C9*C$3 -> 0.027798035 | D16: =+D9*D$3 -> 0.028064646 | E16: =+E9*E$3 -> 0.028618365 | F16: =+F9*F$3 -> 0.032768238 | G16: =+G9*G$3 -> 0.03372055 | H16: =+H9*H$3 -> 0.029928558 | I16: =+I9*I$3 -> 0.023282591 | J16: =+J9*J$3 -> 0.022797523 | ... AJ16: =+AJ9*AJ$3 -> 0.010185772
A17: Final Exergy Energy industry own use [TJ] | B17: Computed | C17: =+C10*C$3 -> 0.078343711 | D17: =+D10*D$3 -> 0.069833206 | E17: =+E10*E$3 -> 0.06453802 | F17: =+F10*F$3 -> 0.066730424 | G17: =+G10*G$3 -> 0.05243729 | H17: =+H10*H$3 -> 0.060798684 | I17: =+I10*I$3 -> 0.068792975 | J17: =+J10*J$3 -> 0.06915366 | ... AJ17: =+AJ10*AJ$3 -> 0.078531474
A19: Share final exergy industry electricity | B19: Input | C19: 0.2970747 | D19: 0.30075756 | E19: 0.30235708 | F19: 0.30163627 | G19: 0.30591526 | H19: 0.31318182 | I19: 0.31035417 | J19: 0.31226091 | K19: 0.31416765 | L19: 0.31607439 | M19: 0.31798114 | N19: 0.31988788 | O19: 0.32179462 | P19: 0.32370136 | Q19: 0.32560811 | R19: 0.32751485 | S19: 0.32863758 | T19: 0.32990769 | U19: 0.33117295 | V19: 0.3324334 | W19: 0.33368904 | X19: 0.33493993 | Y19: 0.33618607 | Z19: 0.33742751 | AA19: 0.33866425 | AB19: 0.33989634 | AC19: 0.34031391 | AD19: 0.34062099 | AE19: 0.34092529 | AF19: 0.34122685 | AG19: 0.3415257 | AH19: 0.34182189 | AI19: 0.34211544 | AJ19: 0.3424064
A20: Share final exergy transport electricity | B20: Input | C20: 0.0068374586 | D20: 0.0068392983 | E20: 0.0067376336 | F20: 0.0070045484 | G20: 0.0070586514 | H20: 0.0070199832 | I20: 0.0076482888 | J20: 0.0079060577 | K20: 0.0081638265 | L20: 0.0084215954 | M20: 0.0086793642 | N20: 0.0089371331 | O20: 0.0091949019 | P20: 0.0094526708 | Q20: 0.0097104396 | R20: 0.0099682085 | S20: 0.010225977 | T20: 0.010483746 | U20: 0.010741515 | V20: 0.010999284 | W20: 0.011257053 | X20: 0.011514822 | Y20: 0.01177259 | Z20: 0.012030359 | AA20: 0.012288128 | AB20: 0.012545897 | AC20: 0.012803666 | AD20: 0.013061435 | AE20: 0.013319204 | AF20: 0.013576972 | AG20: 0.013834741 | AH20: 0.01409251 | AI20: 0.014350279 | AJ20: 0.014608048
A21: Share final exergy services electricity | B21: Input | C21: 0.73677033 | D21: 0.72971057 | E21: 0.73192341 | F21: 0.7583611 | G21: 0.73914204 | H21: 0.75301205 | I21: 0.74281677 | J21: 0.7426465 | K21: 0.74247623 | L21: 0.74230596 | M21: 0.74213569 | N21: 0.74196542 | O21: 0.74179514 | P21: 0.74162487 | Q21: 0.7414546 | R21: 0.74128433 | S21: 0.74111406 | T21: 0.74094379 | U21: 0.74077351 | V21: 0.74060324 | W21: 0.73947303 | X21: 0.73855213 | Y21: 0.73763311 | Z21: 0.73671595 | AA21: 0.73580065 | AB21: 0.7348872 | AC21: 0.73397559 | AD21: 0.73306583 | AE21: 0.7321579 | AF21: 0.7312518 | AG21: 0.73034752 | AH21: 0.72944507 | AI21: 0.72854442 | AJ21: 0.72764558
A22: Share final exergy residencial electricity | B22: Input | C22: 0.40105887 | D22: 0.41096146 | E22: 0.41088932 | F22: 0.40750368 | G22: 0.42720606 | H22: 0.43001357 | I22: 0.43031559 | J22: 0.43471854 | K22: 0.43912148 | L22: 0.44352443 | M22: 0.44792737 | N22: 0.45233032 | O22: 0.45673326 | P22: 0.4611362 | Q22: 0.46553915 | R22: 0.46994209 | S22: 0.47434504 | T22: 0.47874798 | U22: 0.48315092 | V22: 0.48755387 | W22: 0.49195681 | X22: 0.49635976 | Y22: 0.5007627 | Z22: 0.50516565 | AA22: 0.50956859 | AB22: 0.51397153 | AC22: 0.51837448 | AD22: 0.52277742 | AE22: 0.52718037 | AF22: 0.53158331 | AG22: 0.53367957 | AH22: 0.53499611 | AI22: 0.53629772 | AJ22: 0.53758466
A23: Share final exergy Agriculture/forestry/Fishing electricity | B23: Input | C23: 0.17678412 | D23: 0.18850159 | E23: 0.16560611 | F23: 0.16584001 | G23: 0.17929811 | H23: 0.16275005 | I23: 0.1699724 | J23: 0.17022649 | K23: 0.17048058 | L23: 0.17073467 | M23: 0.17098875 | N23: 0.17124284 | O23: 0.17149693 | P23: 0.17175101 | Q23: 0.1720051 | R23: 0.17225919 | S23: 0.17251327 | T23: 0.17276736 | U23: 0.17302145 | V23: 0.17327553 | W23: 0.17352962 | X23: 0.17378371 | Y23: 0.1740378 | Z23: 0.17429188 | AA23: 0.17439466 | AB23: 0.17454626 | AC23: 0.17469768 | AD23: 0.17484892 | AE23: 0.17499999 | AF23: 0.17515087 | AG23: 0.17530159 | AH23: 0.17545212 | AI23: 0.17560249 | AJ23: 0.17575267
A24: Share final exergy Energy industry own electricity | B24: Input | C24: 0.20857445 | D24: 0.19412629 | E24: 0.17649312 | F24: 0.17373555 | G24: 0.18464616 | H24: 0.17476388 | I24: 0.17891093 | J24: 0.17800461 | K24: 0.1770983 | L24: 0.17619199 | M24: 0.17528568 | N24: 0.17437936 | O24: 0.17347305 | P24: 0.17256674 | Q24: 0.17166043 | R24: 0.17075411 | S24: 0.1698478 | T24: 0.16894149 | U24: 0.16803518 | V24: 0.16712886 | W24: 0.16622255 | X24: 0.16531624 | Y24: 0.16440993 | Z24: 0.16350361 | AA24: 0.1625973 | AB24: 0.16169099 | AC24: 0.16078468 | AD24: 0.15987836 | AE24: 0.15897205 | AF24: 0.15767591 | AG24: 0.15626303 | AH24: 0.1548593 | AI24: 0.15346461 | AJ24: 0.15207889
A25: Share final exergy industry coal/coke | B25: Input | C25: 0.069253404 | D25: 0.061170092 | E25: 0.059562702 | F25: 0.064743037 | G25: 0.054408395 | H25: 0.06007097 | I25: 0.052651272 | J25: 0.049897148 | K25: 0.047143024 | L25: 0.0443889 | M25: 0.041634776 | N25: 0.038880651 | O25: 0.036126527 | P25: 0.033372403 | Q25: 0.030618279 | R25: 0.027864155 | S25: 0.025050269 | T25: 0.02226005 | U25: 0.019480483 | V25: 0.016711505 | W25: 0.013953057 | X25: 0.011205079 | Y25: 0.0084675118 | Z25: 0.0057402957 | AA25: 0.0030233723 | AB25: 0.00031668355 | AC25: 0 | AD25: 0 | AE25: 0 | AF25: 0 | AG25: 0 | AH25: 0 | AI25: 0 | AJ25: 0
A26: Share final exergy industry oil | B26: Input | C26: 0.078378662 | D26: 0.077637821 | E26: 0.069863979 | F26: 0.070795621 | G26: 0.069265914 | H26: 0.082289434 | I26: 0.070176562 | J26: 0.068490573 | K26: 0.066804585 | L26: 0.065118597 | M26: 0.063432608 | N26: 0.06174662 | O26: 0.060060632 | P26: 0.058374643 | Q26: 0.056688655 | R26: 0.055002667 | S26: 0.053189786 | T26: 0.051409312 | U26: 0.049635634 | V26: 0.047868715 | W26: 0.046108514 | X26: 0.044354994 | Y26: 0.042608118 | Z26: 0.040867846 | AA26: 0.039134143 | AB26: 0.03740697 | AC26: 0.035601566 | AD26: 0.033800828 | AE26: 0.032016382 | AF26: 0.030248008 | AG26: 0.02849549 | AH26: 0.026758615 | AI26: 0.025037175 | AJ26: 0.023330965
A27: Share final exergy industry natural gas | B27: Input | C27: 0.27024948 | D27: 0.2755297 | E27: 0.27458465 | F27: 0.2640436 | G27: 0.29137166 | H27: 0.25694602 | I27: 0.28170259 | J27: 0.28512852 | K27: 0.28855445 | L27: 0.29198037 | M27: 0.2954063 | N27: 0.29883222 | O27: 0.30225815 | P27: 0.30568408 | Q27: 0.30911 | R27: 0.31253593 | S27: 0.31520988 | T27: 0.31801834 | U27: 0.32081607 | V27: 0.32360315 | W27: 0.32637964 | X27: 0.32914558 | Y27: 0.33190104 | Z27: 0.33464609 | AA27: 0.33738077 | AB27: 0.34010516 | AC27: 0.34200538 | AD27: 0.34378158 | AE27: 0.3455417 | AF27: 0.34728598 | AG27: 0.34901461 | AH27: 0.35072781 | AI27: 0.35242579 | AJ27: 0.35410875
A28: Share final exergy industry waste/c. renewables | B28: Input | C28: 0.26201817 | D28: 0.25876213 | E28: 0.26551584 | F28: 0.27237961 | G28: 0.25652296 | H28: 0.27022414 | I28: 0.26829567 | J28: 0.26932365 | K28: 0.27035164 | L28: 0.27137962 | M28: 0.2724076 | N28: 0.27343558 | O28: 0.27446356 | P28: 0.27549155 | Q28: 0.27651953 | R28: 0.27754751 | S28: 0.27791249 | T28: 0.27840461 | U28: 0.27889486 | V28: 0.27938323 | W28: 0.27986975 | X28: 0.28035442 | Y28: 0.28083725 | Z28: 0.28131826 | AA28: 0.28179746 | AB28: 0.28227485 | AC28: 0.28207914 | AD28: 0.28179661 | AE28: 0.28151663 | AF28: 0.28123917 | AG28: 0.2809642 | AH28: 0.28069169 | AI28: 0.28042159 | AJ28: 0.28015389
A29: Share final exergy industry heat | B29: Input | C29: 0.023025582 | D29: 0.026142703 | E29: 0.028115736 | F29: 0.026401859 | G29: 0.022515809 | H29: 0.017287611 | I29: 0.016819733 | J29: 0.014899195 | K29: 0.012978657 | L29: 0.011058119 | M29: 0.0091375808 | N29: 0.0072170427 | O29: 0.0052965046 | P29: 0.0033759665 | Q29: 0.0014554284 | R29: -0.0004651097 | S29: 0 | T29: 0 | U29: 0 | V29: 0 | W29: 0 | X29: 0 | Y29: 0 | Z29: 0 | AA29: 0 | AB29: 0 | AC29: 0 | AD29: 0 | AE29: 0 | AF29: 0 | AG29: 0 | AH29: 0 | AI29: 0 | AJ29: =+AI29*(1-AJ$19)/(1-AI$19) -> 0
A30: Share final exergy transport coal/coke | B30: Input | C30: 0 | D30: 0 | E30: 0 | F30: 0 | G30: 0 | H30: 0 | I30: 0 | J30: 0 | K30: 0 | L30: 0 | M30: 0 | N30: 0 | O30: 0 | P30: 0 | Q30: 0 | R30: 0 | S30: 0 | T30: 0 | U30: 0 | V30: 0 | W30: 0 | X30: 0 | Y30: 0 | Z30: 0 | AA30: 0 | AB30: 0 | AC30: 0 | AD30: 0 | AE30: 0 | AF30: 0 | AG30: 0 | AH30: 0 | AI30: 0 | AJ30: 0
A31: Share final exergy transport oil | B31: Input | C31: 0.94650317 | D31: 0.94323568 | E31: 0.94252362 | F31: 0.93788625 | G31: 0.92726817 | H31: 0.92771702 | I31: 0.93231343 | J31: 0.93126882 | K31: 0.93022422 | L31: 0.92917962 | M31: 0.92813502 | N31: 0.92709042 | O31: 0.92604581 | P31: 0.92500121 | Q31: 0.92395661 | R31: 0.92291201 | S31: 0.92186741 | T31: 0.9208228 | U31: 0.9197782 | V31: 0.9187336 | W31: 0.917689 | X31: 0.9166444 | Y31: 0.91559979 | Z31: 0.91455519 | AA31: 0.91351059 | AB31: 0.91246599 | AC31: 0.91142139 | AD31: 0.91037678 | AE31: 0.90933218 | AF31: 0.90828758 | AG31: 0.90724298 | AH31: 0.90619838 | AI31: 0.90515377 | AJ31: 0.90410917
A32: Share final exergy transport natural gas | B32: Input | C32: 0.0025002831 | D32: 0.0026990588 | E32: 0.0028751385 | F32: 0.0039454464 | G32: 0.0042923769 | H32: 0.0055594064 | I32: 0.0047571423 | J32: 0.0050449742 | K32: 0.0053328061 | L32: 0.0056206379 | M32: 0.0059084698 | N32: 0.0061963017 | O32: 0.0064841335 | P32: 0.0067719654 | Q32: 0.0070597972 | R32: 0.0073476291 | S32: 0.007635461 | T32: 0.0079232928 | U32: 0.0082111247 | V32: 0.0084989566 | W32: 0.0087867884 | X32: 0.0090746203 | Y32: 0.0093624521 | Z32: 0.009650284 | AA32: 0.0099381159 | AB32: 0.010225948 | AC32: 0.01051378 | AD32: 0.010801611 | AE32: 0.011089443 | AF32: 0.011377275 | AG32: 0.011665107 | AH32: 0.011952939 | AI32: 0.012240771 | AJ32: 0.012528603
A33: Share final exergy transport c. renewables/waste | B33: Input | C33: 0.044159087 | D33: 0.047225959 | E33: 0.047863611 | F33: 0.051163753 | G33: 0.061380802 | H33: 0.059703595 | I33: 0.055281142 | J33: 0.055780143 | K33: 0.056279145 | L33: 0.056778146 | M33: 0.057277147 | N33: 0.057776149 | O33: 0.05827515 | P33: 0.058774151 | Q33: 0.059273152 | R33: 0.059772154 | S33: 0.060271155 | T33: 0.060770156 | U33: 0.061269158 | V33: 0.061768159 | W33: 0.06226716 | X33: 0.062766161 | Y33: 0.063265163 | Z33: 0.063764164 | AA33: 0.064263165 | AB33: 0.064762167 | AC33: 0.065261168 | AD33: 0.065760169 | AE33: 0.06625917 | AF33: 0.066758172 | AG33: 0.067257173 | AH33: 0.067756174 | AI33: 0.068255175 | AJ33: 0.068754177
A34: Share final exergy transport heat | B34: Input | C34: 0 | D34: 0 | E34: 0 | F34: 0 | G34: 0 | H34: 0 | I34: 0 | J34: 0 | K34: 0 | L34: 0 | M34: 0 | N34: 0 | O34: 0 | P34: 0 | Q34: 0 | R34: 0 | S34: 0 | T34: 0 | U34: 0 | V34: 0 | W34: 0 | X34: 0 | Y34: 0 | Z34: 0 | AA34: 0 | AB34: 0 | AC34: 0 | AD34: 0 | AE34: 0 | AF34: 0 | AG34: 0 | AH34: 0 | AI34: 0 | AJ34: 0
A35: Share final exergy services coal/coke | B35: Input | C35: 0 | D35: 0 | E35: 0 | F35: 0 | G35: 0 | H35: 0 | I35: 0 | J35: 0 | K35: 0 | L35: 0 | M35: 0 | N35: 0 | O35: 0 | P35: 0 | Q35: 0 | R35: 0 | S35: 0 | T35: 0 | U35: 0 | V35: 0 | W35: 0 | X35: 0 | Y35: 0 | Z35: 0 | AA35: 0 | AB35: 0 | AC35: 0 | AD35: 0 | AE35: 0 | AF35: 0 | AG35: 0 | AH35: 0 | AI35: 0 | AJ35: 0
A36: Share final exergy services oil | B36: Input | C36: 0.077348966 | D36: 0.087056264 | E36: 0.090620219 | F36: 0.073143915 | G36: 0.066652382 | H36: 0.066249945 | I36: 0.071929211 | J36: 0.070741379 | K36: 0.069553547 | L36: 0.068365715 | M36: 0.067177884 | N36: 0.065990052 | O36: 0.06480222 | P36: 0.063614388 | Q36: 0.062426556 | R36: 0.061238724 | S36: 0.060050893 | T36: 0.058863061 | U36: 0.057675229 | V36: 0.056487397 | W36: 0.055227871 | X36: 0.053986694 | Y36: 0.052748036 | Z36: 0.051511889 | AA36: 0.050278244 | AB36: 0.049047096 | AC36: 0.047818436 | AD36: 0.046592256 | AE36: 0.045368549 | AF36: 0.044147308 | AG36: 0.042928525 | AH36: 0.041712192 | AI36: 0.040498303 | AJ36: 0.03928685
A37: Share final exergy services natural gas | B37: Input | C37: 0.13908516 | D37: 0.13780262 | E37: 0.13277494 | F37: 0.1231687 | G37: 0.14388299 | H37: 0.13039761 | I37: 0.13838598 | J37: 0.13973149 | K37: 0.14107701 | L37: 0.14242252 | M37: 0.14376803 | N37: 0.14511355 | O37: 0.14645906 | P37: 0.14780457 | Q37: 0.14915009 | R37: 0.1504956 | S37: 0.15184112 | T37: 0.15318663 | U37: 0.15453214 | V37: 0.15587766 | W37: 0.15701934 | X37: 0.15820227 | Y37: 0.1593828 | Z37: 0.16056095 | AA37: 0.1617367 | AB37: 0.16291008 | AC37: 0.16408108 | AD37: 0.16524973 | AE37: 0.16641601 | AF37: 0.16757994 | AG37: 0.16874154 | AH37: 0.16990079 | AI37: 0.17105772 | AJ37: 0.17221233
A38: Share final exergy services c. renewables/waste | B38: Input | C38: 0.019601913 | D38: 0.018216043 | E38: 0.01642892 | F38: 0.01284449 | G38: 0.016374281 | H38: 0.01770829 | I38: 0.012953268 | J38: 0.01193531 | K38: 0.010917351 | L38: 0.0098993929 | M38: 0.0088814346 | N38: 0.0078634762 | O38: 0.0068455179 | P38: 0.0058275596 | Q38: 0.0048096013 | R38: 0.003791643 | S38: 0.0027736846 | T38: 0.0017557263 | U38: 0.00073776801 | V38: -0.00028019031 | W38: 0 | X38: 0 | Y38: 0 | Z38: 0 | AA38: 0 | AB38: 0 | AC38: 0 | AD38: 0 | AE38: 0 | AF38: 0 | AG38: 0 | AH38: 0 | AI38: 0 | AJ38: 0
A39: Share final exergy services renewables | B39: Input | C39: 0.019231307 | D39: 0.019644153 | E39: 0.020836864 | F39: 0.024392322 | G39: 0.02544208 | H39: 0.025857495 | I39: 0.026444102 | J39: 0.027523279 | K39: 0.028602456 | L39: 0.029681633 | M39: 0.030760809 | N39: 0.031839986 | O39: 0.032919163 | P39: 0.03399834 | Q39: 0.035077516 | R39: 0.036156693 | S39: 0.03723587 | T39: 0.038315047 | U39: 0.039394224 | V39: 0.0404734 | W39: 0.041498706 | X39: 0.042533242 | Y39: 0.04356568 | Z39: 0.044596024 | AA39: 0.045624283 | AB39: 0.04665046 | AC39: 0.047674565 | AD39: 0.048696601 | AE39: 0.049716576 | AF39: 0.050734497 | AG39: 0.051750368 | AH39: 0.052764196 | AI39: 0.053775988 | AJ39: 0.05478575
A40: Share final exergy services heat | B40: Input | C40: 0.0079623246 | D40: 0.0075703452 | E40: 0.0074156469 | F40: 0.008089469 | G40: 0.0085062263 | H40: 0.0067746151 | I40: 0.0074706676 | J40: 0.0074220389 | K40: 0.0073734101 | L40: 0.0073247813 | M40: 0.0072761526 | N40: 0.0072275238 | O40: 0.0071788951 | P40: 0.0071302663 | Q40: 0.0070816375 | R40: 0.0070330088 | S40: 0.00698438 | T40: 0.0069357513 | U40: 0.0068871225 | V40: 0.0068384937 | W40: 0.0067810621 | X40: 0.0067256589 | Y40: 0.006670368 | Z40: 0.0066151892 | AA40: 0.0065601222 | AB40: 0.0065051666 | AC40: 0.006450322 | AD40: 0.0063955881 | AE40: 0.0063409647 | AF40: 0.0062864513 | AG40: 0.0062320476 | AH40: 0.0061777533 | AI40: 0.0061235681 | AJ40: 0.0060694916
A41: Share final exergy residencial coal/coke | B41: Input | C41: 0 | D41: 0 | E41: 0 | F41: 0 | G41: 0 | H41: 0 | I41: 0 | J41: 0 | K41: 0 | L41: 0 | M41: 0 | N41: 0 | O41: 0 | P41: 0 | Q41: 0 | R41: 0 | S41: 0 | T41: 0 | U41: 0 | V41: 0 | W41: 0 | X41: 0 | Y41: 0 | Z41: 0 | AA41: 0 | AB41: 0 | AC41: 0 | AD41: 0 | AE41: 0 | AF41: 0 | AG41: 0 | AH41: 0 | AI41: 0 | AJ41: 0
... A46: Share final exergy residencial heat | B46: Input | C46: 0.00019113704 | D46: 0.00022897677 | E46: 0.000186438 | F46: 0.00017904391 | G46: 0.00017952454 | H46: 0.00012876039 | I46: 0.00015578395 | J46: 0.00014960057 | K46: 0.00014341719 | L46: 0.00013723381 | M46: 0.00013105043 | N46: 0.00012486705 | O46: 0.00011868366 | P46: 0.00011250028 | Q46: 0.0001063169 | R46: 0.00010013352 | S46: 9.3950138e-05 | T46: 8.7766756e-05 | U46: 8.1583375e-05 | V46: 7.5399993e-05 | W46: 6.9216611e-05 | X46: 6.303323e-05 | Y46: 5.6849848e-05 | Z46: 5.0666467e-05 | AA46: 4.4483085e-05 | AB46: 3.8299703e-05 | AC46: 3.2116322e-05 | AD46: 2.593294e-05 | AE46: 1.9749559e-05 | AF46: 1.3566177e-05 | AG46: 7.3510228e-06 | AH46: 1.1874438e-06 | AI46: -4.9062574e-06 | AJ46: -1.0931262e-05
A47: Share final exergy Agriculture/Forestry/Fishing Coal/Coke | B47: Input | C47: 0 | D47: 0 | E47: 0 | F47: 0 | G47: 0 | H47: 0 | I47: =+H47*(1-I$23)/(1-H$23) -> 0 | J47: =+I47*(1-J$23)/(1-I$23) -> 0 | K47: =+J47*(1-K$23)/(1-J$23) -> 0 | L47: =+K47*(1-L$23)/(1-K$23) -> 0 | M47: =+L47*(1-M$23)/(1-L$23) -> 0 | N47: =+M47*(1-N$23)/(1-M$23) -> 0 | O47: =+N47*(1-O$23)/(1-N$23) -> 0 | P47: =+O47*(1-P$23)/(1-O$23) -> 0 | ... AJ47: =+AI47*(1-AJ$23)/(1-AI$23) -> 0
...

Sheet BAU
A1: Scenarios - BAU 2025-2050 | C1: Historical | D1: Historical | E1: Historical | F1: Historical | G1: Historical | H1: Historical | I1: Scenarios
C2: 2017 | D2: 2018 | E2: 2019 | F2: 2020 | G2: 2021 | H2: 2022 | I2: 2023 | J2: 2024 | K2: 2025 | L2: 2026 | M2: 2027 | N2: 2028 | O2: 2029 | P2: 2030 | Q2: 2031 | R2: 2032 | S2: 2033 | T2: 2034 | U2: 2035 | V2: 2036 | W2: 2037 | X2: 2038 | Y2: 2039 | Z2: 2040 | AA2: 2041 | AB2: 2042 | AC2: 2043 | AD2: 2044 | AE2: 2045 | AF2: 2046 | AG2: 2047 | AH2: 2048 | AI2: 2049 | AJ2: 2050
A3: New Solar power [GW] | B3: Computed | D3: =D10-C10 -> 0.098 | E3: =E10-D10 -> 0.253 | F3: =F10-E10 -> 0.221 | G3: =G10-F10 -> 0.626 | H3: =H10-G10 -> 1 | I3: =I10-H10 -> 1.223 | J3: =J10-I10 -> 1.768 | K3: =K10-J10 -> 0.54584615 | ... AJ3: =AJ10-AI10 -> 0.54584615
A4: New Onshore Wind power [GW] | B4: Computed | D4: =D11-C11 -> 0.048 | E4: =E11-D11 -> 0.051 | F4: =F11-E11 -> -0.101 | G4: =G11-F11 -> 0.305 | H4: =H11-G11 -> 0.111 | I4: =I11-H11 -> 0 | J4: =J11-I11 -> 0.045 | K4: =K11-J11 -> 0.0677 | ... AJ4: =AJ11-AI11 -> 0.1427
A5: New Offshore Wind power [GW] | B5: Computed | D5: =D12-C12 -> 0 | E5: =E12-D12 -> 0 | F5: =F12-E12 -> 0.025 | G5: =G12-F12 -> 0 | H5: =H12-G12 -> 0 | I5: =I12-H12 -> 0 | J5: =J12-I12 -> 0 | K5: =K12-J12 -> 0 | ... AJ5: =AJ12-AI12 -> 0
A6: New Batteries [GWh] | B6: Computed | D6: =D13-C13 -> 0 | E6: =E13-D13 -> 0 | F6: =F13-E13 -> 0.02 | G6: =G13-F13 -> 0 | H6: =H13-G13 -> 0.03 | I6: =I13-H13 -> 0 | J6: =J13-I13 -> 0.01 | K6: =K13-J13 -> 0 | ... AJ6: =AJ13-AI13 -> 0
A7: New Hydrogen [GW] | B7: Computed | D7: =D14-C14 -> 0 | E7: =E14-D14 -> 0 | F7: =F14-E14 -> 0 | G7: =G14-F14 -> 0 | H7: =H14-G14 -> 0 | I7: =I14-H14 -> 0 | J7: =J14-I14 -> 0 | K7: =K14-J14 -> 0 | ... AJ7: =AJ14-AI14 -> 0
A8: New Hydropower [GW] | B8: Computed | D8: =D15-C15 -> 0.01 | E8: =E15-D15 -> 0.026 | F8: =F15-E15 -> -0.021 | G8: =G15-F15 -> 0.014 | H8: =H15-G15 -> 0.934 | I8: =I15-H15 -> -0.002 | J8: =J15-I15 -> 0.16 | K8: =K15-J15 -> 0 | ... AJ8: =AJ15-AI15 -> 0
A10: Solar power [GW] | B10: Input | C10: 0.619 | D10: 0.717 | E10: 0.97 | F10: 1.191 | G10: 1.817 | H10: 2.817 | I10: 4.04 | J10: 5.808 | K10: 6.3538462 | L10: 6.8996923 | M10: 7.4455385 | N10: 7.9913846 | O10: 8.5372308 | P10: 9.0830769 | Q10: 9.6289231 | R10: 10.174769 | S10: 10.720615 | T10: 11.266462 | U10: 11.812308 | V10: 12.358154 | W10: 12.904 | X10: 13.449846 | Y10: 13.995692 | Z10: 14.541538 | AA10: 15.087385 | AB10: 15.633231 | AC10: 16.179077 | AD10: 16.724923 | AE10: 17.270769 | AF10: 17.816615 | AG10: 18.362462 | AH10: 18.908308 | AI10: 19.454154 | AJ10: 20
A11: Onshore Wind power [GW] | B11: Input | C11: 5.124 | D11: 5.172 | E11: 5.223 | F11: 5.122 | G11: 5.427 | H11: 5.538 | I11: 5.538 | J11: 5.583 | K11: 5.6507 | L11: 5.7214 | M11: 5.7951 | N11: 5.8718 | O11: 5.9515 | P11: 6.0342 | Q11: 6.1199 | R11: 6.2086 | S11: 6.3003 | T11: 6.395 | U11: 6.4927 | V11: 6.5934 | W11: 6.6971 | X11: 6.8038 | Y11: 6.9135 | Z11: 7.0262 | AA11: 7.1419 | AB11: 7.2606 | AC11: 7.3823 | AD11: 7.507 | AE11: 7.6347 | AF11: 7.7654 | AG11: 7.8991 | AH11: 8.0358 | AI11: 8.1755 | AJ11: 8.3182
A12: Offshore Wind Power [GW] | B12: Input | C12: 0 | D12: 0 | E12: 0 | F12: 0.025 | G12: 0.025 | H12: 0.025 | I12: 0.025 | J12: 0.025 | K12: 0.025 | L12: 0.025 | M12: 0.025 | N12: 0.025 | O12: 0.025 | P12: 0.025 | Q12: 0.025 | R12: 0.025 | S12: 0.025 | T12: 0.025 | U12: 0.025 | V12: 0.025 | W12: 0.025 | X12: 0.025 | Y12: 0.025 | Z12: 0.025 | AA12: 0.025 | AB12: 0.025 | AC12: 0.025 | AD12: 0.025 | AE12: 0.025 | AF12: 0.025 | AG12: 0.025 | AH12: 0.025 | AI12: 0.025 | AJ12: 0.025
A13: Batteries [GWh] | B13: Input | C13: 0 | D13: 0 | E13: 0 | F13: 0.02 | G13: 0.02 | H13: 0.05 | I13: 0.05 | J13: 0.06 | K13: 0.06 | L13: 0.06 | M13: 0.06 | N13: 0.06 | O13: 0.06 | P13: 0.06 | Q13: 0.06 | R13: 0.06 | S13: 0.06 | T13: 0.06 | U13: 0.06 | V13: 0.06 | W13: 0.06 | X13: 0.06 | Y13: 0.06 | Z13: 0.06 | AA13: 0.06 | AB13: 0.06 | AC13: 0.06 | AD13: 0.06 | AE13: 0.06 | AF13: 0.06 | AG13: 0.06 | AH13: 0.06 | AI13: 0.06 | AJ13: 0.06
A14: Hydrogen [GW] | B14: Input | C14: 0 | D14: 0 | E14: 0 | F14: 0 | G14: 0 | H14: 0 | I14: 0 | J14: 0 | K14: 0 | L14: 0 | M14: 0 | N14: 0 | O14: 0 | P14: 0 | Q14: 0 | R14: 0 | S14: 0 | T14: 0 | U14: 0 | V14: 0 | W14: 0 | X14: 0 | Y14: 0 | Z14: 0 | AA14: 0 | AB14: 0 | AC14: 0 | AD14: 0 | AE14: 0 | AF14: 0 | AG14: 0 | AH14: 0 | AI14: 0 | AJ14: 0
A15: Hydro power [GW] | B15: Input | C15: 7.226 | D15: 7.236 | E15: 7.262 | F15: 7.241 | G15: 7.255 | H15: 8.189 | I15: 8.187 | J15: 8.347 | K15: 8.347 | L15: 8.347 | M15: 8.347 | N15: 8.347 | O15: 8.347 | P15: 8.347 | Q15: 8.347 | R15: 8.347 | S15: 8.347 | T15: 8.347 | U15: 8.347 | V15: 8.347 | W15: 8.347 | X15: 8.347 | Y15: 8.347 | Z15: 8.347 | AA15: 8.347 | AB15: 8.347 | AC15: 8.347 | AD15: 8.347 | AE15: 8.347 | AF15: 8.347 | AG15: 8.347 | AH15: 8.347 | AI15: 8.347 | AJ15: 8.347
A16: Total Renewable [GW] | C16: =SUM(C10:C15) -> 12.969 | D16: =SUM(D10:D15) -> 13.125 | E16: =SUM(E10:E15) -> 13.455 | F16: =SUM(F10:F15) -> 13.599 | G16: =SUM(G10:G15) -> 14.544 | H16: =SUM(H10:H15) -> 16.619 | I16: =SUM(I10:I15) -> 17.84 | J16: =SUM(J10:J15) -> 19.823 | ... AJ16: =SUM(AJ10:AJ15) -> 36.7502
A18: Cost per GW solar [Euro/GW] | B18: Input | C18: 1446720000 | D18: 1236400000 | E18: 1021680000 | F18: 896720000 | G18: 836000000 | H18: 799040000 | I18: 667040000 | J18: 5.2253277e+08 | K18: 4.4974812e+08 | L18: 3.8710179e+08 | M18: 3.331816e+08 | N18: 2.8677206e+08 | O18: 2.46827e+08 | P18: 2.1244597e+08 | Q18: 1.8285394e+08 | R18: 1.5738384e+08 | S18: 1.3546153e+08 | T18: 1.1659282e+08 | U18: 1.0035237e+08 | V18: 100000000 | W18: 100000000 | X18: 100000000 | Y18: 100000000 | Z18: 100000000 | AA18: 100000000 | AB18: 100000000 | AC18: 100000000 | AD18: 100000000 | AE18: 100000000 | AF18: 100000000 | AG18: 100000000 | AH18: 100000000 | AI18: 100000000 | AJ18: 100000000
A19: Cost per GW of Onshore wind [Euro/GW] | B19: Input | C19: 1686960000 | D19: 1600720000 | E19: 1518000000 | F19: 1365760000 | G19: 1294480000 | H19: 1163360000 | I19: 1020800000 | J19: 1.0655588e+09 | K19: 1.0135909e+09 | L19: 9.6415749e+08 | M19: 9.1713498e+08 | N19: 8.7240578e+08 | O19: 8.2985805e+08 | P19: 7.8938539e+08 | Q19: 7.5088661e+08 | R19: 7.1426544e+08 | S19: 6.794303e+08 | T19: 6.462941e+08 | U19: 6.1477396e+08 | V19: 5.8479108e+08 | W19: 5.5627048e+08 | X19: 5.2914085e+08 | Y19: 5.0333435e+08 | Z19: 4.7878644e+08 | AA19: 4.5543575e+08 | AB19: 4.3322389e+08 | AC19: 4.1209531e+08 | AD19: 3.9199718e+08 | AE19: 3.7287926e+08 | AF19: 3.5469372e+08 | AG19: 3.373951e+08 | AH19: 3.2094015e+08 | AI19: 3.0528771e+08 | AJ19: 2.9039866e+08
A20: Cost per GW of Offshore wind [Euro/GW] | B20: Input | C20: 4788960000 | D20: 4684240000 | E20: 4684240000 | F20: 3753200000 | G20: 3177680000 | H20: 2785200000 | I20: 3060640000 | J20: 2464000000 | K20: 2.7915727e+09 | L20: 2.6554261e+09 | M20: 2.5259195e+09 | N20: 2.4027289e+09 | O20: 2.2855464e+09 | P20: 2.174079e+09 | Q20: 2.0680479e+09 | R20: 1.9671881e+09 | S20: 1.8712472e+09 | T20: 1.7799854e+09 | U20: 1.6931744e+09 | V20: 1.6105974e+09 | W20: 1.5320476e+09 | X20: 1.4573288e+09 | Y20: 1.386254e+09 | Z20: 1.3186456e+09 | AA20: 1.2543345e+09 | AB20: 1.1931599e+09 | AC20: 1.1349688e+09 | AD20: 1.0796157e+09 | AE20: 1.0269622e+09 | AF20: 9.7687668e+08 | AG20: 9.2923384e+08 | AH20: 8.8391457e+08 | AI20: 8.4080555e+08 | AJ20: 7.9979898e+08
A21: Cost per GW batteries [Euro/GW] | B21: Input | C21: 660000000 | D21: 616000000 | E21: 281600000 | F21: 264000000 | G21: 249040000 | H21: 315040000 | I21: 240240000 | J21: 1.5698899e+08 | K21: 1.2853171e+08 | L21: 1.0523287e+08 | M21: 86157384 | N21: 70539700 | O21: 57753021 | P21: 47284175 | Q21: 38713008 | R21: 31695530 | S21: 30000000 | T21: 30000000 | U21: 30000000 | V21: 30000000 | W21: 30000000 | X21: 30000000 | Y21: 30000000 | Z21: 30000000 | AA21: 30000000 | AB21: 30000000 | AC21: 30000000 | AD21: 30000000 | AE21: 30000000 | AF21: 30000000 | AG21: 30000000 | AH21: 30000000 | AI21: 30000000 | AJ21: 30000000
A22: Cost per GW hydrogen [Euro/GW] | B22: Input | C22: 880000000 | D22: 880000000 | E22: 880000000 | F22: 880000000 | G22: 8.5653333e+08 | H22: 8.3306667e+08 | I22: 809600000 | J22: 7.8613333e+08 | K22: 7.6266667e+08 | L22: 739200000 | M22: 7.1573333e+08 | N22: 6.9226667e+08 | O22: 668800000 | P22: 6.4533333e+08 | Q22: 6.2186667e+08 | R22: 598400000 | S22: 5.7493333e+08 | T22: 5.5146667e+08 | U22: 528000000 | V22: 5.0453333e+08 | W22: 4.8106667e+08 | X22: 457600000 | Y22: 4.3413333e+08 | Z22: 4.1066667e+08 | AA22: 387200000 | AB22: 3.6373333e+08 | AC22: 3.4026667e+08 | AD22: 316800000 | AE22: 2.9333333e+08 | AF22: 2.6986667e+08 | AG22: 246400000 | AH22: 2.2293333e+08 | AI22: 1.9946667e+08 | AJ22: 176000000
A23: Cost per GW hydropower [Euro/GW] | B23: Input | C23: 1874400000 | D23: 1468720000 | E23: 1806640000 | F23: 1892880000 | G23: 2081200000 | H23: 2686640000 | I23: 2469280000 | J23: 2469280000 | K23: 2469280000 | L23: 2469280000 | M23: 2469280000 | N23: 2469280000 | O23: 2469280000 | P23: 2469280000 | Q23: 2469280000 | R23: 2469280000 | S23: 2469280000 | T23: 2469280000 | U23: 2469280000 | V23: 2469280000 | W23: 2469280000 | X23: 2469280000 | Y23: 2469280000 | Z23: 2469280000 | AA23: 2469280000 | AB23: 2469280000 | AC23: 2469280000 | AD23: 2469280000 | AE23: 2469280000 | AF23: 2469280000 | AG23: 2469280000 | AH23: 2469280000 | AI23: 2469280000 | AJ23: 2469280000
A25: Cost Solar [Euro] | B25: Computed | C25: =+C18*C3 -> 0 | D25: =+D18*D3 -> 1.211672e+08 | E25: =+E18*E3 -> 258485040 | F25: =+F18*F3 -> 1.9817512e+08 | G25: =+G18*G3 -> 5.23336e+08 | H25: =+H18*H3 -> 7.9904e+08 | I25: =+I18*I3 -> 8.1578992e+08 | J25: =+J18*J3 -> 9.2383793e+08 | ... AJ25: =+AJ18*AJ3 -> 54584615
A26: Cost Onshore Wind [Euro] | B26: Computed | C26: =+C19*C4 -> 0 | D26: =+D19*D4 -> 76834560 | E26: =+E19*E4 -> 77418000 | F26: =+F19*F4 -> -1.3794176e+08 | G26: =+G19*G4 -> 3.948164e+08 | H26: =+H19*H4 -> 1.2913296e+08 | I26: =+I19*I4 -> 0 | J26: =+J19*J4 -> 47950147 | ... AJ26: =+AJ19*AJ4 -> 41439888
A27: Cost Offshore Wind [Euro] | B27: Computed | D27: =+D20*D5 -> 0 | E27: =+E20*E5 -> 0 | F27: =+F20*F5 -> 93830000 | G27: =+G20*G5 -> 0 | H27: =+H20*H5 -> 0 | I27: =+I20*I5 -> 0 | J27: =+J20*J5 -> 0 | K27: =+K20*K5 -> 0 | ... AJ27: =+AJ20*AJ5 -> 0
A28: Cost Batteries [Euro] | B28: Computed | D28: =+D21*D6 -> 0 | E28: =+E21*E6 -> 0 | F28: =+F21*F6 -> 5280000 | G28: =+G21*G6 -> 0 | H28: =+H21*H6 -> 9451200 | I28: =+I21*I6 -> 0 | J28: =+J21*J6 -> 1569889.9 | K28: =+K21*K6 -> 0 | ... AJ28: =+AJ21*AJ6 -> 0
A29: Cost Hydropower [Euro] | B29: Computed | D29: =+D23*D7 -> 0 | E29: =+E23*E7 -> 0 | F29: =+F23*F7 -> 0 | G29: =+G23*G7 -> 0 | H29: =+H23*H7 -> 0 | I29: =+I23*I7 -> 0 | J29: =+J23*J7 -> 0 | K29: =+K23*K7 -> 0 | ... AJ29: =+AJ23*AJ7 -> 0
A30: Cost tot [Mrd Euros] | B30: Computed | C30: =+(SUM(C25:C29)/10^9) -> 0 | D30: =+(SUM(D25:D29)/10^9) -> 0.19800176 | E30: =+(SUM(E25:E29)/10^9) -> 0.33590304 | F30: =+(SUM(F25:F29)/10^9) -> 0.15934336 | G30: =+(SUM(G25:G29)/10^9) -> 0.9181524 | H30: =+(SUM(H25:H29)/10^9) -> 0.93762416 | I30: =+(SUM(I25:I29)/10^9) -> 0.81578992 | J30: =+(SUM(J25:J29)/10^9) -> 0.97335797 | ... AJ30: =+(SUM(AJ25:AJ29)/10^9) -> 0.096024504
A33: Investment Industry [Mrd Euros] | B33: Computed | C33: 8.0532 | D33: 8.5546 | E33: 8.5605 | F33: 8.3117 | G33: 9.503 | H33: 10.0172 | I33: =0.182512988419182*H64 -> 8.718413 | J33: =0.182512988419182*I64 -> 6.7362148 | K33: =0.182512988419182*J64 -> 6.686337 | L33: =0.182512988419182*K64 -> 6.6210117 | M33: =0.182512988419182*L64 -> 6.5556282 | N33: =0.182512988419182*M64 -> 6.4900621 | O33: =0.182512988419182*N64 -> 6.4240236 | P33: =0.182512988419182*O64 -> 6.3575657 | ... AJ33: =0.182512988419182*AI64 -> 5.1661596
A34: Investment Transport [Mrd Euros] | B34: Computed | C34: 1.9438 | D34: 1.8375 | E34: 2.0515 | F34: 1.9884 | G34: 2.1811 | H34: 2.6349 | I34: =0.140684457604253*H65 -> 1.8913891 | J34: =0.140684457604253*I65 -> 1.4613673 | K34: =0.140684457604253*J65 -> 1.4505467 | L34: =0.140684457604253*K65 -> 1.4363749 | M34: =0.140684457604253*L65 -> 1.4221904 | N34: =0.140684457604253*M65 -> 1.4079664 | O34: =0.140684457604253*N65 -> 1.3936399 | P34: =0.140684457604253*O65 -> 1.3792224 | ... AJ34: =0.140684457604253*AI65 -> 1.1207565
A35: Investment Residential [Mrd EURO] | B35: Computed | C35: 5.3217 | D35: 5.663 | E35: 5.7613 | F35: 5.3511 | G35: 6.1815 | H35: 6.3237 | I35: =0.201851534153057*H66 -> 4.9412385 | J35: =0.201851534153057*I66 -> 3.81781 | K35: =0.201851534153057*J66 -> 3.7895413 | L35: =0.201851534153057*K66 -> 3.7525176 | M35: =0.201851534153057*L66 -> 3.7154609 | N35: =0.201851534153057*M66 -> 3.6783007 | O35: =0.201851534153057*N66 -> 3.6408728 | P35: =0.201851534153057*O66 -> 3.6032072 | ... AJ35: =0.201851534153057*AI66 -> 2.9279672
A36: Investment Services [Mrd EURO] | B36: Computed | C36: 16.9093 | D36: 17.9789 | E36: 19.5213 | F36: 19.3649 | G36: 19.9656 | H36: 20.5271 | I36: =0.160891037874836*H67 -> 17.978707 | J36: =0.160891037874836*I67 -> 13.89111 | K36: =0.160891037874836*J67 -> 13.788254 | L36: =0.160891037874836*K67 -> 13.653543 | M36: =0.160891037874836*L67 -> 13.518712 | N36: =0.160891037874836*M67 -> 13.383505 | O36: =0.160891037874836*N67 -> 13.247323 | P36: =0.160891037874836*O67 -> 13.110277 | ... AJ36: =0.160891037874836*AI67 -> 10.653415
A37: Investment Agriculture/Forestry/Fishing [Mrd EURO] | B37: Computed | C37: 1.1382 | D37: 1.1194 | E37: 1.129 | F37: 1.1885 | G37: 1.2523 | H37: 1.1821 | I37: =0.120203494864176*H68 -> 1.185555 | J37: =0.120203494864176*I68 -> 0.91600998 | K37: =0.120203494864176*J68 -> 0.90922746 | L37: =0.120203494864176*K68 -> 0.90034433 | M37: =0.120203494864176*L68 -> 0.89145329 | N37: =0.120203494864176*M68 -> 0.88253742 | O37: =0.120203494864176*N68 -> 0.87355732 | P37: =0.120203494864176*O68 -> 0.86452019 | ... AJ37: =0.120203494864176*AI68 -> 0.70250934
A38: Total Investment | B38: Computed | C38: =+SUM(C33:C37) -> 33.3662 | D38: =+SUM(D33:D37) -> 35.1534 | E38: =+SUM(E33:E37) -> 37.0236 | F38: =+SUM(F33:F37) -> 36.2046 | G38: =+SUM(G33:G37) -> 39.0835 | H38: =+SUM(H33:H37) -> 40.685 | I38: =+SUM(I33:I37) -> 34.715302 | J38: =+SUM(J33:J37) -> 26.822512 | ... AJ38: =+SUM(AJ33:AJ37) -> 20.570807
A40: Depreciation Industry [Mrd Euros] | B40: Computed | C40: 6.8306 | D40: 7.0159 | E40: 7.2788 | F40: 7.507 | G40: 7.657 | H40: 7.9939 | I40: =0.0854053900119604*H47 -> 7.5248554 | J40: =0.0854053900119604*I47 -> 7.6267916 | K40: =0.0854053900119604*J47 -> 7.5507316 | L40: =0.0854053900119604*K47 -> 7.4769076 | M40: =0.0854053900119604*L47 -> 7.4038095 | N40: =0.0854053900119604*M47 -> 7.3313703 | O40: =0.0854053900119604*N47 -> 7.259518 | P40: =0.0854053900119604*O47 -> 7.1881623 | ... AJ40: =0.0854053900119604*AI47 -> 5.8480355
A41: Depreciation Transport [Mrd Euros] | B41: Computed | C41: 1.9801 | D41: 1.9425 | E41: 1.97 | F41: 2.011 | G41: 2.2206 | H41: 2.2665 | I41: =0.0747889159710027*H48 -> 2.0418122 | J41: =0.0747889159710027*I48 -> 2.0305622 | K41: =0.0747889159710027*J48 -> 1.9879927 | L41: =0.0747889159710027*K48 -> 1.9477977 | M41: =0.0747889159710027*L48 -> 1.909549 | N41: =0.0747889159710027*M48 -> 1.8731 | O41: =0.0747889159710027*N48 -> 1.8383131 | P41: =0.0747889159710027*O48 -> 1.8050565 | ... AJ41: =0.0747889159710027*AI48 -> 1.3391822
A42: Depreciation Residential [Mrd EURO] | B42: Computed | C42: 9.368 | D42: 9.2889 | E42: 9.2216 | F42: 9.158 | G42: 9.082 | H42: 9.0321 | I42: =0.0386761793725209*H49 -> 8.7241432 | J42: =0.0386761793725209*I49 -> 8.5778349 | K42: =0.0386761793725209*J49 -> 8.3937354 | L42: =0.0386761793725209*K49 -> 8.2156627 | M42: =0.0386761793725209*L49 -> 8.0430453 | N42: =0.0386761793725209*M49 -> 7.8756709 | O42: =0.0386761793725209*N49 -> 7.7133326 | P42: =0.0386761793725209*O49 -> 7.5558255 | ... AJ42: =0.0386761793725209*AI49 -> 5.1860419
A43: Depreciation Services [Mrd EURO] | B43: Computed | C43: 16.7645 | D43: 17.1296 | E43: 17.6437 | F43: 18.4122 | G43: 18.4823 | H43: 19.0888 | I43: =0.0973324743081864*H50 -> 17.682011 | J43: =0.0973324743081864*I50 -> 17.710889 | K43: =0.0973324743081864*J50 -> 17.339101 | L43: =0.0973324743081864*K50 -> 16.993488 | M43: =0.0973324743081864*L50 -> 16.668403 | N43: =0.0973324743081864*M50 -> 16.361836 | O43: =0.0973324743081864*N50 -> 16.071947 | P43: =0.0973324743081864*O50 -> 15.79702 | ... AJ43: =0.0973324743081864*AI50 -> 12.017849
A44: Depreciation Agriculture/Forestry/Fishing [Mrd EURO] | B44: Computed | C44: 1.0005 | D44: 0.9901 | E44: 0.9827 | F44: 0.9994 | G44: 1.0046 | H44: 1.0195 | I44: =0.0980065492623211*H51 -> 1.0826195 | J44: =0.0980065492623211*I51 -> 1.0927079 | K44: =0.0980065492623211*J51 -> 1.0753903 | L44: =0.0980065492623211*K51 -> 1.0591053 | M44: =0.0980065492623211*L51 -> 1.0435457 | N44: =0.0980065492623211*M51 -> 1.0286396 | O44: =0.0980065492623211*N51 -> 1.0143207 | P44: =0.0980065492623211*O51 -> 1.0005249 | ... AJ44: =0.0980065492623211*AI51 -> 0.78656287
A45: Total Depreciation | B45: Computed | C45: =+SUM(C40:C44) -> 35.9437 | D45: =+SUM(D40:D44) -> 36.367 | E45: =+SUM(E40:E44) -> 37.0968 | F45: =+SUM(F40:F44) -> 38.0876 | G45: =+SUM(G40:G44) -> 38.4465 | H45: =+SUM(H40:H44) -> 39.4008 | I45: =SUM(I40:I44) -> 37.055441 | J45: =SUM(J40:J44) -> 37.038786 | K45: =SUM(K40:K44) -> 36.346951 | L45: =SUM(L40:L44) -> 35.692961 | M45: =SUM(M40:M44) -> 35.068352 | N45: =SUM(N40:N44) -> 34.470616 | O45: =SUM(O40:O44) -> 33.897432 | P45: =SUM(P40:P44) -> 33.346589 | ... AJ45: =SUM(AJ40:AJ44) -> 25.177672
A47: Capital Industry [Mrd Euros] | B47: Computed | C47: 80.6131 | D47: 82.1518 | E47: 83.4335 | F47: 84.2382 | G47: 86.0842 | H47: 88.1075 | I47: =+H47+I33-I40 -> 89.301058 | J47: =+I47+J33-J40 -> 88.410481 | K47: =+J47+K33-K40 -> 87.546086 | L47: =+K47+L33-L40 -> 86.69019 | M47: =+L47+M33-M40 -> 85.842009 | N47: =+M47+N33-N40 -> 85.000701 | O47: =+N47+O33-O40 -> 84.165206 | P47: =+O47+P33-P40 -> 83.33461 | ... AJ47: =+AI47+AJ33-AJ40 -> 67.79197
...

Sheet Aggregate_Efficiency_Decarboniz
A1: Scenarios from 2023 onwards - National Roadmap 2050
C2: 2017 | D2: 2018 | E2: 2019 | F2: 2020 | G2: 2021 | H2: 2022 | I2: 2023 | J2: 2024 | K2: 2025 | L2: 2026 | M2: 2027 | N2: 2028 | O2: 2029 | P2: 2030 | Q2: 2031 | R2: 2032 | S2: 2033 | T2: 2034 | U2: 2035 | V2: 2036 | W2: 2037 | X2: 2038 | Y2: 2039 | Z2: 2040 | AA2: 2041 | AB2: 2042 | AC2: 2043 | AD2: 2044 | AE2: 2045 | AF2: 2046 | AG2: 2047 | AH2: 2048 | AI2: 2049 | AJ2: 2050
A3: Total Final exergy [TJ] | C3: 1 | D3: 1 | E3: 1 | F3: 1 | G3: 1 | H3: 1 | I3: 1 | J3: 1 | K3: 1 | L3: 1 | M3: 1 | N3: 1 | O3: 1 | P3: 1 | Q3: 1 | R3: 1 | S3: 1 | T3: 1 | U3: 1 | V3: 1 | W3: 1 | X3: 1 | Y3: 1 | Z3: 1 | AA3: 1 | AB3: 1 | AC3: 1 | AD3: 1 | AE3: 1 | AF3: 1 | AG3: 1 | AH3: 1 | AI3: 1 | AJ3: 1
A5: Share final exergy industry [-] | B5: Input | C5: 0.27142931 | D5: 0.27119604 | E5: 0.2732505 | F5: 0.28555072 | G5: 0.28462773 | H5: 0.27572585 | I5: 0.27588512 | J5: 0.27604439 | K5: 0.27620366 | L5: 0.27636293 | M5: 0.2765222 | N5: 0.27668146 | O5: 0.27684073 | P5: 0.277 | Q5: 0.2833 | R5: 0.2896 | S5: 0.2959 | T5: 0.3022 | U5: 0.3085 | V5: 0.3148 | W5: 0.3211 | X5: 0.3274 | Y5: 0.3337 | Z5: 0.34 | AA5: 0.3445 | AB5: 0.349 | AC5: 0.3535 | AD5: 0.358 | AE5: 0.3625 | AF5: 0.367 | AG5: 0.3715 | AH5: 0.376 | AI5: 0.3805 | AJ5: 0.385
A6: Share final exergy transport [-] | B6: Input | C6: 0.3546432 | D6: 0.35679786 | E6: 0.36315882 | F6: 0.32899597 | G6: 0.34997126 | H6: 0.36009084 | I6: 0.35382948 | J6: 0.34756813 | K6: 0.34130677 | L6: 0.33504542 | M6: 0.32878406 | N6: 0.32252271 | O6: 0.31626135 | P6: 0.31 | Q6: 0.302 | R6: 0.294 | S6: 0.286 | T6: 0.278 | U6: 0.27 | V6: 0.262 | W6: 0.254 | X6: 0.246 | Y6: 0.238 | Z6: 0.23 | AA6: 0.226 | AB6: 0.222 | AC6: 0.218 | AD6: 0.214 | AE6: 0.21 | AF6: 0.206 | AG6: 0.202 | AH6: 0.198 | AI6: 0.194 | AJ6: 0.19
A7: Share final exergy services [-] | B7: Input | C7: 0.11098227 | D7: 0.11418082 | E7: 0.11117733 | F7: 0.10630522 | G7: 0.10424487 | H7: 0.10934643 | I7: 0.11442812 | J7: 0.11950982 | K7: 0.12459152 | L7: 0.12967321 | M7: 0.13475491 | N7: 0.13983661 | O7: 0.1449183 | P7: 0.15 | Q7: 0.15 | R7: 0.15 | S7: 0.15 | T7: 0.15 | U7: 0.15 | V7: 0.15 | W7: 0.15 | X7: 0.15 | Y7: 0.15 | Z7: 0.15 | AA7: 0.152 | AB7: 0.154 | AC7: 0.156 | AD7: 0.158 | AE7: 0.16 | AF7: 0.162 | AG7: 0.164 | AH7: 0.166 | AI7: 0.168 | AJ7: 0.17
A8: Share final exergy residencial [-] | B8: Input | C8: 0.15680348 | D8: 0.15992742 | E8: 0.15925696 | F8: 0.17964943 | G8: 0.17499831 | H8: 0.16410964 | I8: 0.16609594 | J8: 0.16808223 | K8: 0.17006853 | L8: 0.17205482 | M8: 0.17404112 | N8: 0.17602741 | O8: 0.17801371 | P8: 0.18 | Q8: 0.182 | R8: 0.184 | S8: 0.186 | T8: 0.188 | U8: 0.19 | V8: 0.192 | W8: 0.194 | X8: 0.196 | Y8: 0.198 | Z8: 0.2 | AA8: 0.198 | AB8: 0.196 | AC8: 0.194 | AD8: 0.192 | AE8: 0.19 | AF8: 0.188 | AG8: 0.186 | AH8: 0.184 | AI8: 0.182 | AJ8: 0.18
A9: Share Final Exergy Agriculture/forestry/Fishing [-] | B9: Input | C9: 0.027798035 | D9: 0.028064646 | E9: 0.028618365 | F9: 0.032768238 | G9: 0.03372055 | H9: 0.029928558 | I9: 0.029937488 | J9: 0.029946419 | K9: 0.029955349 | L9: 0.029964279 | M9: 0.029973209 | N9: 0.02998214 | O9: 0.02999107 | P9: 0.03 | Q9: 0.03 | R9: 0.03 | S9: 0.03 | T9: 0.03 | U9: 0.03 | V9: 0.03 | W9: 0.03 | X9: 0.03 | Y9: 0.03 | Z9: 0.03 | AA9: 0.03 | AB9: 0.03 | AC9: 0.03 | AD9: 0.03 | AE9: 0.03 | AF9: 0.03 | AG9: 0.03 | AH9: 0.03 | AI9: 0.03 | AJ9: 0.03
A10: Share Final Exergy Energy industry own use [-] | B10: Input | C10: 0.078343711 | D10: 0.069833206 | E10: 0.06453802 | F10: 0.066730424 | G10: 0.05243729 | H10: 0.060798684 | I10: 0.059823848 | J10: 0.058849013 | K10: 0.057874177 | L10: 0.056899342 | M10: 0.055924506 | N10: 0.054949671 | O10: 0.053974835 | P10: 0.053 | Q10: 0.0527 | R10: 0.0524 | S10: 0.0521 | T10: 0.0518 | U10: 0.0515 | V10: 0.0512 | W10: 0.0509 | X10: 0.0506 | Y10: 0.0503 | Z10: 0.05 | AA10: 0.0495 | AB10: 0.049 | AC10: 0.0485 | AD10: 0.048 | AE10: 0.0475 | AF10: 0.047 | AG10: 0.0465 | AH10: 0.046 | AI10: 0.0455 | AJ10: 0.045
A12: Final exergy Industry [TJ] | B12: Computed | C12: =+C5*C$3 -> 0.27142931 | D12: =+D5*D$3 -> 0.27119604 | E12: =+E5*E$3 -> 0.2732505 | F12: =+F5*F$3 -> 0.28555072 | G12: =+G5*G$3 -> 0.28462773 | H12: =+H5*H$3 -> 0.27572585 | I12: =+I5*I$3 -> 0.27588512 | J12: =+J5*J$3 -> 0.27604439 | ... AJ12: =+AJ5*AJ$3 -> 0.385
A13: Final exergy Transport [TJ] | B13: Computed | C13: =+C6*C$3 -> 0.3546432 | D13: =+D6*D$3 -> 0.35679786 | E13: =+E6*E$3 -> 0.36315882 | F13: =+F6*F$3 -> 0.32899597 | G13: =+G6*G$3 -> 0.34997126 | H13: =+H6*H$3 -> 0.36009084 | I13: =+I6*I$3 -> 0.35382948 | J13: =+J6*J$3 -> 0.34756813 | ... AJ13: =+AJ6*AJ$3 -> 0.19
A14: Final exergy Services [TJ] | B14: Computed | C14: =+C7*C$3 -> 0.11098227 | D14: =+D7*D$3 -> 0.11418082 | E14: =+E7*E$3 -> 0.11117733 | F14: =+F7*F$3 -> 0.10630522 | G14: =+G7*G$3 -> 0.10424487 | H14: =+H7*H$3 -> 0.10934643 | I14: =+I7*I$3 -> 0.11442812 | J14: =+J7*J$3 -> 0.11950982 | ... AJ14: =+AJ7*AJ$3 -> 0.17
A15: Final exergy Residencial [TJ] | B15: Computed | C15: =+C8*C$3 -> 0.15680348 | D15: =+D8*D$3 -> 0.15992742 | E15: =+E8*E$3 -> 0.15925696 | F15: =+F8*F$3 -> 0.17964943 | G15: =+G8*G$3 -> 0.17499831 | H15: =+H8*H$3 -> 0.16410964 | I15: =+I8*I$3 -> 0.16609594 | J15: =+J8*J$3 -> 0.16808223 | ... AJ15: =+AJ8*AJ$3 -> 0.18
A16: Final Exergy Agriculture/Forestry/fishing [TJ] | B16: Computed | C16: =+C9*C$3 -> 0.027798035 | D16: =+D9*D$3 -> 0.028064646 | E16: =+E9*E$3 -> 0.028618365 | F16: =+F9*F$3 -> 0.032768238 | G16: =+G9*G$3 -> 0.03372055 | H16: =+H9*H$3 -> 0.029928558 | I16: =+I9*I$3 -> 0.029937488 | J16: =+J9*J$3 -> 0.029946419 | ... AJ16: =+AJ9*AJ$3 -> 0.03
A17: Final Exergy Energy industry own use [TJ] | B17: Computed | C17: =+C10*C$3 -> 0.078343711 | D17: =+D10*D$3 -> 0.069833206 | E17: =+E10*E$3 -> 0.06453802 | F17: =+F10*F$3 -> 0.066730424 | G17: =+G10*G$3 -> 0.05243729 | H17: =+H10*H$3 -> 0.060798684 | I17: =+I10*I$3 -> 0.059823848 | J17: =+J10*J$3 -> 0.058849013 | ... AJ17: =+AJ10*AJ$3 -> 0.045
A19: Share final exergy industry electricity | B19: Input | C19: 0.2970747 | D19: 0.30075756 | E19: 0.30235708 | F19: 0.30163627 | G19: 0.30591526 | H19: 0.31318182 | I19: 0.31407823 | J19: 0.31497465 | K19: 0.31587106 | L19: 0.31676747 | M19: 0.31766388 | N19: 0.31856029 | O19: 0.3194567 | P19: 0.32035311 | Q19: 0.32710662 | R19: 0.33386012 | S19: 0.34061363 | T19: 0.34736713 | U19: 0.35412063 | V19: 0.36087414 | W19: 0.36762764 | X19: 0.37438115 | Y19: 0.38113465 | Z19: 0.38788815 | AA19: 0.40440244 | AB19: 0.42091672 | AC19: 0.43743101 | AD19: 0.45394529 | AE19: 0.47045958 | AF19: 0.48697386 | AG19: 0.50348815 | AH19: 0.52000243 | AI19: 0.53651672 | AJ19: 0.553031
A20: Share final exergy transport electricity | B20: Input | C20: 0.0068374586 | D20: 0.0068392983 | E20: 0.0067376336 | F20: 0.0070045484 | G20: 0.0070586514 | H20: 0.0070199832 | I20: 0.020547839 | J20: 0.034075694 | K20: 0.04760355 | L20: 0.061131405 | M20: 0.074659261 | N20: 0.088187116 | O20: 0.10171497 | P20: 0.11524283 | Q20: 0.15554516 | R20: 0.1958475 | S20: 0.23614984 | T20: 0.27645218 | U20: 0.31675451 | V20: 0.35705685 | W20: 0.39735919 | X20: 0.43766153 | Y20: 0.47796386 | Z20: 0.5182662 | AA20: 0.53528284 | AB20: 0.55229949 | AC20: 0.56931613 | AD20: 0.58633277 | AE20: 0.60334941 | AF20: 0.62036606 | AG20: 0.6373827 | AH20: 0.65439934 | AI20: 0.67141598 | AJ20: 0.68843263
A21: Share final exergy services electricity | B21: Input | C21: 0.73677033 | D21: 0.72971057 | E21: 0.73192341 | F21: 0.7583611 | G21: 0.73914204 | H21: 0.75301205 | I21: 0.75138554 | J21: 0.74975904 | K21: 0.74813253 | L21: 0.74650602 | M21: 0.74487952 | N21: 0.74325301 | O21: 0.74162651 | P21: 0.74 | Q21: 0.748 | R21: 0.756 | S21: 0.764 | T21: 0.772 | U21: 0.78 | V21: 0.788 | W21: 0.796 | X21: 0.804 | Y21: 0.812 | Z21: 0.82 | AA21: 0.826 | AB21: 0.832 | AC21: 0.838 | AD21: 0.844 | AE21: 0.85 | AF21: 0.856 | AG21: 0.862 | AH21: 0.868 | AI21: 0.874 | AJ21: 0.88
A22: Share final exergy residencial electricity | B22: Input | C22: 0.40105887 | D22: 0.41096146 | E22: 0.41088932 | F22: 0.40750368 | G22: 0.42720606 | H22: 0.43001357 | I22: 0.43126188 | J22: 0.43251018 | K22: 0.43375848 | L22: 0.43500679 | M22: 0.43625509 | N22: 0.43750339 | O22: 0.4387517 | P22: 0.44 | Q22: 0.459 | R22: 0.478 | S22: 0.497 | T22: 0.516 | U22: 0.535 | V22: 0.554 | W22: 0.573 | X22: 0.592 | Y22: 0.611 | Z22: 0.63 | AA22: 0.65 | AB22: 0.67 | AC22: 0.69 | AD22: 0.71 | AE22: 0.73 | AF22: 0.75 | AG22: 0.77 | AH22: 0.79 | AI22: 0.81 | AJ22: 0.83
A23: Share final exergy Agriculture/forestry/Fishing electricity | B23: Input | C23: 0.17678412 | D23: 0.18850159 | E23: 0.16560611 | F23: 0.16584001 | G23: 0.17929811 | H23: 0.16275005 | I23: 0.18979469 | J23: 0.21683933 | K23: 0.24388397 | L23: 0.27092861 | M23: 0.29797325 | N23: 0.3250179 | O23: 0.35206254 | P23: 0.37910718 | Q23: 0.40615182 | R23: 0.43319646 | S23: 0.4602411 | T23: 0.48728574 | U23: 0.51433038 | V23: 0.54137502 | W23: 0.56841967 | X23: 0.59546431 | Y23: 0.62250895 | Z23: 0.64955359 | AA23: 0.67659823 | AB23: 0.70364287 | AC23: 0.73068751 | AD23: 0.75773215 | AE23: 0.78477679 | AF23: 0.81182144 | AG23: 0.83886608 | AH23: 0.86591072 | AI23: 0.89295536 | AJ23: 0.92
A24: Share final exergy Energy industry own electricity | B24: Input | C24: 0.20857445 | D24: 0.19412629 | E24: 0.17649312 | F24: 0.17373555 | G24: 0.18464616 | H24: 0.17476388 | I24: 0.20066517 | J24: 0.22656646 | K24: 0.25246775 | L24: 0.27836904 | M24: 0.30427033 | N24: 0.33017162 | O24: 0.35607291 | P24: 0.3819742 | Q24: 0.40787549 | R24: 0.43377678 | S24: 0.45967807 | T24: 0.48557936 | U24: 0.51148065 | V24: 0.53738194 | W24: 0.56328323 | X24: 0.58918452 | Y24: 0.61508581 | Z24: 0.6409871 | AA24: 0.66688839 | AB24: 0.69278968 | AC24: 0.71869097 | AD24: 0.74459226 | AE24: 0.77049355 | AF24: 0.79639484 | AG24: 0.82229613 | AH24: 0.84819742 | AI24: 0.87409871 | AJ24: 0.9
A25: Share final exergy industry coal/coke | B25: Input | C25: 0.069253404 | D25: 0.061170092 | E25: 0.059562702 | F25: 0.064743037 | G25: 0.054408395 | H25: 0.06007097 | I25: 0.052788926 | J25: 0.045506881 | K25: 0.038224837 | L25: 0.030942793 | M25: 0.023660748 | N25: 0.016378704 | O25: 0.0090966594 | P25: 0.001814615 | Q25: 0.0018311542 | R25: 0.0018476934 | S25: 0.0018642325 | T25: 0.0018807717 | U25: 0.0018973109 | V25: 0.0019138501 | W25: 0.0019303892 | X25: 0.0019469284 | Y25: 0.0019634676 | Z25: 0.0019800068 | AA25: 0.0019856155 | AB25: 0.0019912243 | AC25: 0.0019968331 | AD25: 0.0020024418 | AE25: 0.0020080506 | AF25: 0.0020136593 | AG25: 0.0020192681 | AH25: 0.0020248769 | AI25: 0.0020304856 | AJ25: 0.0020360944
A26: Share final exergy industry oil | B26: Input | C26: 0.078378662 | D26: 0.077637821 | E26: 0.069863979 | F26: 0.070795621 | G26: 0.069265914 | H26: 0.082289434 | I26: 0.072199429 | J26: 0.062109425 | K26: 0.05201942 | L26: 0.041929415 | M26: 0.031839411 | N26: 0.021749406 | O26: 0.011659401 | P26: 0.0015693968 | Q26: 0.0015235306 | R26: 0.0014776645 | S26: 0.0014317984 | T26: 0.0013859323 | U26: 0.0013400661 | V26: 0.0012942 | W26: 0.0012483339 | X26: 0.0012024678 | Y26: 0.0011566016 | Z26: 0.0011107355 | AA26: 0.0010922117 | AB26: 0.0010736879 | AC26: 0.0010551641 | AD26: 0.0010366403 | AE26: 0.0010181165 | AF26: 0.00099959267 | AG26: 0.00098106887 | AH26: 0.00096254506 | AI26: 0.00094402126 | AJ26: 0.00092549745
A27: Share final exergy industry natural gas | B27: Input | C27: 0.27024948 | D27: 0.2755297 | E27: 0.27458465 | F27: 0.2640436 | G27: 0.29137166 | H27: 0.25694602 | I27: 0.26313699 | J27: 0.26932796 | K27: 0.27551892 | L27: 0.28170989 | M27: 0.28790086 | N27: 0.29409183 | O27: 0.30028279 | P27: 0.30647376 | Q27: 0.29764509 | R27: 0.28881643 | S27: 0.27998776 | T27: 0.27115909 | U27: 0.26233042 | V27: 0.25350176 | W27: 0.24467309 | X27: 0.23584442 | Y27: 0.22701575 | Z27: 0.21818709 | AA27: 0.20882557 | AB27: 0.19946406 | AC27: 0.19010255 | AD27: 0.18074103 | AE27: 0.17137952 | AF27: 0.16201801 | AG27: 0.1526565 | AH27: 0.14329498 | AI27: 0.13393347 | AJ27: 0.12457196
A28: Share final exergy industry waste/c. renewables | B28: Input | C28: 0.26201817 | D28: 0.25876213 | E28: 0.26551584 | F28: 0.27237961 | G28: 0.25652296 | H28: 0.27022414 | I28: 0.25239144 | J28: 0.23455874 | K28: 0.21672604 | L28: 0.19889333 | M28: 0.18106063 | N28: 0.16322793 | O28: 0.14539523 | P28: 0.12756253 | Q28: 0.12657524 | R28: 0.12558796 | S28: 0.12460067 | T28: 0.12361339 | U28: 0.1226261 | V28: 0.12163881 | W28: 0.12065153 | X28: 0.11966424 | Y28: 0.11867696 | Z28: 0.11768967 | AA28: 0.11565694 | AB28: 0.1136242 | AC28: 0.11159147 | AD28: 0.10955873 | AE28: 0.107526 | AF28: 0.10549327 | AG28: 0.10346053 | AH28: 0.1014278 | AI28: 0.099395066 | AJ28: 0.097362332
A29: Share final exergy industry Renewables (Solar) | B29: Input | C29: 0 | D29: 0 | E29: 0 | F29: 0 | G29: 0 | H29: 0 | I29: 0.0008521334 | J29: 0.0017042668 | K29: 0.0025564002 | L29: 0.0034085336 | M29: 0.004260667 | N29: 0.0051128004 | O29: 0.0059649338 | P29: 0.0068170672 | Q29: 0.0071736567 | R29: 0.0075302462 | S29: 0.0078868357 | T29: 0.0082434252 | U29: 0.0086000147 | V29: 0.0089566042 | W29: 0.0093131938 | X29: 0.0096697833 | Y29: 0.010026373 | Z29: 0.010382962 | AA29: 0.012093393 | AB29: 0.013803825 | AC29: 0.015514256 | AD29: 0.017224687 | AE29: 0.018935118 | AF29: 0.02064555 | AG29: 0.022355981 | AH29: 0.024066412 | AI29: 0.025776843 | AJ29: 0.027487274
A30: Share final exergy industry heat | B30: Input | C30: 0.023025582 | D30: 0.026142703 | E30: 0.028115736 | F30: 0.026401859 | G30: 0.022515809 | H30: 0.017287611 | I30: 0.044552849 | J30: 0.071818087 | K30: 0.099083325 | L30: 0.12634856 | M30: 0.1536138 | N30: 0.18087904 | O30: 0.20814428 | P30: 0.23540951 | Q30: 0.2381447 | R30: 0.24087989 | S30: 0.24361508 | T30: 0.24635026 | U30: 0.24908545 | V30: 0.25182064 | W30: 0.25455582 | X30: 0.25729101 | Y30: 0.2600262 | Z30: 0.26276139 | AA30: 0.25594383 | AB30: 0.24912628 | AC30: 0.24230872 | AD30: 0.23549117 | AE30: 0.22867361 | AF30: 0.22185606 | AG30: 0.2150385 | AH30: 0.20822095 | AI30: 0.20140339 | AJ30: 0.19458584
... A58: Share Final Exergy Energy industry own use Heat | B58: Input | C58: 0.11153732 | D58: 0.12514663 | E58: 0.13516367 | F58: 0.14874172 | G58: 0.13776063 | H58: 0.069597049 | I58: 0.069254297 | J58: 0.068911545 | K58: 0.068568794 | L58: 0.068226042 | M58: 0.06788329 | N58: 0.067540538 | O58: 0.067197787 | P58: 0.066855035 | Q58: 0.066512283 | R58: 0.066169531 | S58: 0.06582678 | T58: 0.065484028 | U58: 0.065141276 | V58: 0.064798524 | W58: 0.064455773 | X58: 0.064113021 | Y58: 0.063770269 | Z58: 0.063427517 | AA58: 0.063084766 | AB58: 0.062742014 | AC58: 0.062399262 | AD58: 0.06205651 | AE58: 0.061713759 | AF58: 0.061371007 | AG58: 0.061028255 | AH58: 0.060685503 | AI58: 0.060342752 | AJ58: 0.06
A60: Final exergy industry electricity [TJ] | B60: Computed | C60: =+C19*C12 -> 0.08063478 | D60: =+D19*D12 -> 0.081564258 | E60: =+E19*E12 -> 0.082619224 | F60: =+F19*F12 -> 0.086132456 | G60: =+G19*G12 -> 0.087071965 | H60: =+H19*H12 -> 0.086352326 | I60: =+I19*I12 -> 0.086649512 | J60: =+J19*J12 -> 0.086946984 | ... AJ60: =+AJ19*AJ12 -> 0.21291694 | AL60: =+AJ60/$AL$66 -> 0.29953743
A61: Final exergy transport electricity [TJ] | B61: Computed | C61: =+C20*C13 -> 0.0024248582 | D61: =+D20*D13 -> 0.002440247 | E61: =+E20*E13 -> 0.0024468311 | F61: =+F20*F13 -> 0.0023044682 | G61: =+G20*G13 -> 0.0024703251 | H61: =+H20*H13 -> 0.0025278316 | I61: =+I20*I13 -> 0.0072704311 | J61: =+J20*J13 -> 0.011843625 | ... AJ61: =+AJ20*AJ13 -> 0.1308022 | AL61: =+AJ61/$AL$66 -> 0.18401615
A62: Final exergy services electricity [TJ] | B62: Computed | C62: =+C21*C14 -> 0.081768445 | D62: =+D21*D14 -> 0.083318954 | E62: =+E21*E14 -> 0.081373292 | F62: =+F21*F14 -> 0.080617743 | G62: =+G21*G14 -> 0.077051763 | H62: =+H21*H14 -> 0.082339176 | I62: =+I21*I14 -> 0.085979637 | J62: =+J21*J14 -> 0.089603567 | ... AJ62: =+AJ21*AJ14 -> 0.1496 | AL62: =+AJ62/$AL$66 -> 0.21046141
A63: Final exergy residencial electricity [TJ] | B63: Computed | C63: =+C22*C15 -> 0.062887425 | D63: =+D22*D15 -> 0.065724008 | E63: =+E22*E15 -> 0.065436985 | F63: =+F22*F15 -> 0.073207804 | G63: =+G22*G15 -> 0.074760337 | H63: =+H22*H15 -> 0.070569373 | I63: =+I22*I15 -> 0.071630845 | J63: =+J22*J15 -> 0.072697276 | ... AJ63: =+AJ22*AJ15 -> 0.1494 | AL63: =+AJ63/$AL$66 -> 0.21018005
A64: Final Exergy Agriculture/Forestry/fishing electricity [TJ] | B64: Computed | C64: =+C23*C16 -> 0.004914251 | D64: =+D23*D16 -> 0.0052902303 | E64: =+E23*E16 -> 0.0047393761 | F64: =+F23*F16 -> 0.0054342848 | G64: =+G23*G16 -> 0.0060460307 | H64: =+H23*H16 -> 0.0048708743 | I64: =+I23*I16 -> 0.0056819763 | J64: =+J23*J16 -> 0.0064935614 | ... AJ64: =+AJ23*AJ16 -> 0.0276 | AL64: =+AJ64/$AL$66 -> 0.038828443
A65: Final Exergy Energy industry own use electricity [TJ] | B65: Computed | C65: =+C24*C17 -> 0.016340496 | D65: =+D24*D17 -> 0.013556461 | E65: =+E24*E17 -> 0.011390517 | F65: =+F24*F17 -> 0.011593447 | G65: =+G24*G17 -> 0.009682344 | H65: =+H24*H17 -> 0.010625414 | I65: =+I24*I17 -> 0.012004563 | J65: =+J24*J17 -> 0.013333213 | ... AJ65: =+AJ24*AJ17 -> 0.0405 | AL65: =+AJ65/$AL$66 -> 0.056976519
A66: Final exergy industry coal/coke [TJ] | B66: Computed | C66: =+C25*C$12 -> 0.018797403 | D66: =+D25*D$12 -> 0.016589087 | E66: =+E25*E$12 -> 0.016275538 | F66: =+F25*F$12 -> 0.018487421 | G66: =+G25*G$12 -> 0.015486138 | H66: =+H25*H$12 -> 0.01656312 | I66: =+I25*I$12 -> 0.014563679 | J66: =+J25*J$12 -> 0.012561919 | ... AJ66: =+AJ25*AJ$12 -> 0.00078389634 | AL66: =+SUM(AJ60:AJ65) -> 0.71081914
A67: Final exergy industry oil [TJ] | B67: Computed | C67: =+C26*C$12 -> 0.021274266 | D67: =+D26*D$12 -> 0.02105507 | E67: =+E26*E$12 -> 0.019090367 | F67: =+F26*F$12 -> 0.020215741 | G67: =+G26*G$12 -> 0.019715 | H67: =+H26*H$12 -> 0.022689325 | I67: =+I26*I$12 -> 0.019918748 | J67: =+J26*J$12 -> 0.017144958 | ... AJ67: =+AJ26*AJ$12 -> 0.00035631652
A68: Final exergy industry natural gas [TJ] | B68: Computed | C68: =+C27*C$12 -> 0.073353629 | D68: =+D27*D$12 -> 0.074722565 | E68: =+E27*E$12 -> 0.075030393 | F68: =+F27*F$12 -> 0.07539784 | G68: =+G27*G$12 -> 0.082932455 | H68: =+H27*H$12 -> 0.070846662 | I68: =+I27*I$12 -> 0.072595581 | J68: =+J27*J$12 -> 0.074346472 | ... AJ68: =+AJ27*AJ$12 -> 0.047960204
A69: Final exergy industry c. renewables/waste [TJ] | B69: Computed | C69: =+C28*C$12 -> 0.071119412 | D69: =+D28*D$12 -> 0.070175264 | E69: =+E28*E$12 -> 0.072552336 | F69: =+F28*F$12 -> 0.077778194 | G69: =+G28*G$12 -> 0.073013548 | H69: =+H28*H$12 -> 0.074507782 | I69: =+I28*I$12 -> 0.069631043 | J69: =+J28*J$12 -> 0.064748624 | ... AJ69: =+AJ28*AJ$12 -> 0.037484498
A70: Final exergy industry renewables [TJ] | B70: Computed | C70: =+C29*C$12 -> 0 | D70: =+D29*D$12 -> 0 | E70: =+E29*E$12 -> 0 | F70: =+F29*F$12 -> 0 | G70: =+G29*G$12 -> 0 | H70: =+H29*H$12 -> 0 | I70: =+I29*I$12 -> 0.00023509093 | J70: =+J29*J$12 -> 0.00047045329 | ... AJ70: =+AJ29*AJ$12 -> 0.010582601
A71: Final exergy industry heat [TJ] | B71: Computed | C71: =+C30*C$12 -> 0.0062498177 | D71: =+D30*D$12 -> 0.0070897976 | E71: =+E30*E$12 -> 0.0076826389 | F71: =+F30*F$12 -> 0.00753907 | G71: =+G30*G$12 -> 0.0064086236 | H71: =+H30*H$12 -> 0.0047666413 | I71: =+I30*I$12 -> 0.012291468 | J71: =+J30*J$12 -> 0.01982498 | ... AJ71: =+AJ30*AJ$12 -> 0.074915548
...

Sheet Decarbonizatio
A1: Scenarios up to 2050 - National Roadmap 2050
